Workbook
Name Slicer_Headers: #N/A
Name Slicer_Subheaders: #N/A

Sheet Dashboard
A1: #VALUE!
A2: Date & Time | B2: =NOW() -> 45670.433
A3: Project | B3: NAME PROJECT
A4: Finishing level | B4: Medium +0%
A5: Budget | B5: 2000000
A6: Expenses | B6: =Budget_items[[#Totals],[Total]] -> 1751800
A7: Difference | B7: =B5-B6 -> 248200
D13: Budget | E13: 2000000 | F13: 1
D14: Expenses | E14: =Budget_items[[#Totals],[Total]] -> 1751800 | F14: =E14/E13 -> 0.8759
D15: Difference | E15: =E13-E14 -> 248200 | F15: =E15/E14 -> 0.14168284
H19: Amount budget items
H20: =COUNTA(Budget_items[Headers]) -> 89

Sheet Blad2
A1: Rijlabels | B1: Som van Total
A2: 01 - CONSTRUCTION COSTS | B2: 371373
A3: 02 - INSTALLATIONS | B3: 548775
A4: 03 - JOINERY | B4: 153500
A5: 04 - FURNITURE | B5: 126500
A6: 05 - INVENTORY AND DECORATIONS | B6: 101500
A7: 06 - OTHERS | B7: 5700
A8: 07 - CONSULTANCY COSTS | B8: 245000
A9: 08 - CONTINGENCY | B9: 200000
A10: Eindtotaal | B10: 1752348

Sheet Budget
B1: Headers | C1: Subheaders | D1: Code | E1: Description | F1: Quantity | G1: Unit | H1: € / Unit | I1: € / Unit + Finishing | J1: Total
B2: 01 - CONSTRUCTION COSTS | C2: 01.01 - General construction | D2: 1.01.01 | E2: General construction site costs (cleaning, waste, coffee, temporary cylinders etc.) | F2: 4000 | G2: m² | H2: 5 | I2: =Budget_items[[#This Row],[€ / Unit]]*Row!$F$1 -> 5 | J2: =PRODUCT(Budget_items[[#This Row],[Quantity]],Budget_items[[#This Row],[€ / Unit + Finishing]]) -> 20000
B3: 01 - CONSTRUCTION COSTS | C3: 01.01 - General construction | D3: 1.01.02 | E3: Vertical transportation | F3: 3 | G3: day | H3: 1500 | I3: =Budget_items[[#This Row],[€ / Unit]]*Row!$F$1 -> 1500 | J3: =PRODUCT(Budget_items[[#This Row],[Quantity]],Budget_items[[#This Row],[€ / Unit + Finishing]]) -> 4500
B4: 01 - CONSTRUCTION COSTS | C4: 01.01 - General construction | D4: 1.01.03 | E4: Delivery cleaning / final cleaning | F4: 4000 | G4: m² | H4: 4 | I4: =Budget_items[[#This Row],[€ / Unit]]*Row!$F$1 -> 4 | J4: =PRODUCT(Budget_items[[#This Row],[Quantity]],Budget_items[[#This Row],[€ / Unit + Finishing]]) -> 16000
B5: 01 - CONSTRUCTION COSTS | C5: 01.01 - General construction | D5: 1.01.04 | E5: Project coordination (contractor) + parking costs | F5: 0 | G5: weeks | H5: 1500 | I5: =Budget_items[[#This Row],[€ / Unit]]*Row!$F$1 -> 1500 | J5: =PRODUCT(Budget_items[[#This Row],[Quantity]],Budget_items[[#This Row],[€ / Unit + Finishing]]) -> 0
B6: 01 - CONSTRUCTION COSTS | C6: 01.01 - General construction | D6: 1.01.05 | E6: Werktekeningen en revisie | F6: 0 | G6: lot | H6: 2000 | I6: =Budget_items[[#This Row],[€ / Unit]]*Row!$F$1 -> 2000 | J6: =PRODUCT(Budget_items[[#This Row],[Quantity]],Budget_items[[#This Row],[€ / Unit + Finishing]]) -> 0
B7: 01 - CONSTRUCTION COSTS | C7: 01.01 - General construction | D7: 1.01.06 | E7: Overhead + profit and risk + CAR insurance (Ak + wr + carverzekering) | F7: 0 | G7: lot | H7: 0 | I7: =Budget_items[[#This Row],[€ / Unit]]*Row!$F$1 -> 0 | J7: =PRODUCT(Budget_items[[#This Row],[Quantity]],Budget_items[[#This Row],[€ / Unit + Finishing]]) -> 0
B8: 01 - CONSTRUCTION COSTS | C8: 01.01 - General construction | D8: 1.01.07 | E8: * Waste fee (stortleges) (65 euro per m3) | F8: 0 | G8: lot | H8: 2500 | I8: =Budget_items[[#This Row],[€ / Unit]]*Row!$F$1 -> 2500 | J8: =PRODUCT(Budget_items[[#This Row],[Quantity]],Budget_items[[#This Row],[€ / Unit + Finishing]]) -> 0
B9: 01 - CONSTRUCTION COSTS | C9: 01.02 - Demolition | D9: 1.02.01 | E9: Demolition and disposal carpeting | F9: 0 | G9: m² | H9: 5 | I9: =Budget_items[[#This Row],[€ / Unit]]*Row!$F$1 -> 5 | J9: =PRODUCT(Budget_items[[#This Row],[Quantity]],Budget_items[[#This Row],[€ / Unit + Finishing]]) -> 0
B10: 01 - CONSTRUCTION COSTS | C10: 01.02 - Demolition | D10: 1.02.02 | E10: Demolition and disposal partitioning | F10: 0 | G10: m² | H10: 25 | I10: =Budget_items[[#This Row],[€ / Unit]]*Row!$F$1 -> 25 | J10: =PRODUCT(Budget_items[[#This Row],[Quantity]],Budget_items[[#This Row],[€ / Unit + Finishing]]) -> 0
B11: 01 - CONSTRUCTION COSTS | C11: 01.02 - Demolition | D11: 1.02.03 | E11: Demolition and disposal ceiling | F11: 0 | G11: m² | H11: 10 | I11: =Budget_items[[#This Row],[€ / Unit]]*Row!$F$1 -> 10 | J11: =PRODUCT(Budget_items[[#This Row],[Quantity]],Budget_items[[#This Row],[€ / Unit + Finishing]]) -> 0
B12: 01 - CONSTRUCTION COSTS | C12: 01.02 - Demolition | D12: 1.02.04 | E12: Demolition and disposal loose furniture / inventory | F12: 0 | G12: lot | H12: 3500 | I12: =Budget_items[[#This Row],[€ / Unit]]*Row!$F$1 -> 3500 | J12: =PRODUCT(Budget_items[[#This Row],[Quantity]],Budget_items[[#This Row],[€ / Unit + Finishing]]) -> 0
B13: 01 - CONSTRUCTION COSTS | C13: 01.03 - Partitioning | D13: 1.03.01 | E13: * Solid walls including finishes | F13: 500 | G13: m² | H13: 122 | I13: =Budget_items[[#This Row],[€ / Unit]]*Row!$F$1 -> 122 | J13: =PRODUCT(Budget_items[[#This Row],[Quantity]],Budget_items[[#This Row],[€ / Unit + Finishing]]) -> 61000
... B90: 08 - CONTINGENCY | C90: 08.01 - Contingency | D90: 8.01.01 | E90: * Contingency (10-15%) | F90: 1 | G90: lot | H90: 200000 | I90: =Budget_items[[#This Row],[€ / Unit]]*Row!$F$1 -> 200000 | J90: =PRODUCT(Budget_items[[#This Row],[Quantity]],Budget_items[[#This Row],[€ / Unit + Finishing]]) -> 200000
J91: =SUBTOTAL(109,Budget_items[Total]) -> 1751800

Sheet Data entry
A1: Subheaders | B1: Code | D1: New Budget Item | G1: New Subheader | J1: New Header | M1: Headers | N1: Kolom1 | P1: Subheaders | Q1: Kolom2 | R1: Kolom3
A2: =P2 -> 01.01 - General construction | B2: =LEFT(A2,4)&C2 -> 01.0.07 | C2: =IF(COUNTIFS(Budget_items[Subheaders],'Data entry'!A2)<10,".0"&COUNTIFS(Budget_items[Subheaders],'Data entry'!A2),"."&COUNTIFS(Budget_items[Subheaders],'Data entry'!A2)) -> .07 | D2: Headers | G2: Header | J2: Header | M2: 01 - CONSTRUCTION COSTS | N2: =LEFT(M2,2) -> 01 | P2: 01.01 - General construction | Q2: =LEFT(P2,5) -> 01.01 | R2: =SUBSTITUTE(Q2," "&"-","") -> 01.01
A3: =P3 -> 01.02 - Demolition | B3: =LEFT(A3,5)&C3 -> 01.02.04 | C3: =IF(COUNTIFS(Budget_items[Subheaders],'Data entry'!A3)<10,".0"&COUNTIFS(Budget_items[Subheaders],'Data entry'!A3),"."&COUNTIFS(Budget_items[Subheaders],'Data entry'!A3)) -> .04 | D3: Subheaders | G3: Subheader | M3: 02 - INSTALLATIONS | N3: =LEFT(M3,2) -> 02 | P3: 01.02 - Demolition | Q3: =LEFT(P3,5) -> 01.02 | R3: =SUBSTITUTE(Q3," "&"-","") -> 01.02
A4: =P4 -> 01.03 - Partitioning | B4: =LEFT(A4,5)&C4 -> 01.03.07 | C4: =IF(COUNTIFS(Budget_items[Subheaders],'Data entry'!A4)<10,".0"&COUNTIFS(Budget_items[Subheaders],'Data entry'!A4),"."&COUNTIFS(Budget_items[Subheaders],'Data entry'!A4)) -> .07 | D4: Code | E4: =_xlfn.XLOOKUP(E3,A:A,B:B," ") -> 0 | M4: 03 - JOINERY | N4: =LEFT(M4,2) -> 03 | P4: 01.03 - Partitioning | Q4: =LEFT(P4,5) -> 01.03 | R4: =SUBSTITUTE(Q4," "&"-","") -> 01.03
A5: =P5 -> 01.04 - Ceiling | B5: =LEFT(A5,5)&C5 -> 01.04.03 | C5: =IF(COUNTIFS(Budget_items[Subheaders],'Data entry'!A5)<10,".0"&COUNTIFS(Budget_items[Subheaders],'Data entry'!A5),"."&COUNTIFS(Budget_items[Subheaders],'Data entry'!A5)) -> .03 | D5: Description | M5: 04 - FURNITURE | N5: =LEFT(M5,2) -> 04 | P5: 01.04 - Ceiling | Q5: =LEFT(P5,5) -> 01.04 | R5: =SUBSTITUTE(Q5," "&"-","") -> 01.04
A6: =P6 -> 01.05 - Flooring | B6: =LEFT(A6,5)&C6 -> 01.05.09 | C6: =IF(COUNTIFS(Budget_items[Subheaders],'Data entry'!A6)<10,".0"&COUNTIFS(Budget_items[Subheaders],'Data entry'!A6),"."&COUNTIFS(Budget_items[Subheaders],'Data entry'!A6)) -> .09 | D6: Quantity | M6: 05 - INVENTORY AND DECORATIONS | N6: =LEFT(M6,2) -> 05 | P6: 01.05 - Flooring | Q6: =LEFT(P6,5) -> 01.05 | R6: =SUBSTITUTE(Q6," "&"-","") -> 01.05
A7: =P7 -> 01.06 - Painting | B7: =LEFT(A7,5)&C7 -> 01.06.05 | C7: =IF(COUNTIFS(Budget_items[Subheaders],'Data entry'!A7)<10,".0"&COUNTIFS(Budget_items[Subheaders],'Data entry'!A7),"."&COUNTIFS(Budget_items[Subheaders],'Data entry'!A7)) -> .05 | D7: Unit | M7: 06 - OTHERS | N7: =LEFT(M7,2) -> 06 | P7: 01.06 - Painting | Q7: =LEFT(P7,5) -> 01.06 | R7: =SUBSTITUTE(Q7," "&"-","") -> 01.06
A8: =P8 -> 02.01 - Mechanical installation & plumbing | B8: =LEFT(A8,5)&C8 -> 02.01.03 | C8: =IF(COUNTIFS(Budget_items[Subheaders],'Data entry'!A8)<10,".0"&COUNTIFS(Budget_items[Subheaders],'Data entry'!A8),"."&COUNTIFS(Budget_items[Subheaders],'Data entry'!A8)) -> .03 | D8: € / Unit | M8: 07 - CONSULTANCY COSTS | N8: =LEFT(M8,2) -> 07 | P8: 02.01 - Mechanical installation & plumbing | Q8: =LEFT(P8,5) -> 02.01 | R8: =SUBSTITUTE(Q8," "&"-","") -> 02.01
A9: =P9 -> 02.02 - Electrical installation | B9: =LEFT(A9,5)&C9 -> 02.02.06 | C9: =IF(COUNTIFS(Budget_items[Subheaders],'Data entry'!A9)<10,".0"&COUNTIFS(Budget_items[Subheaders],'Data entry'!A9),"."&COUNTIFS(Budget_items[Subheaders],'Data entry'!A9)) -> .06 | M9: 08 - CONTINGENCY | N9: =LEFT(M9,2) -> 08 | P9: 02.02 - Electrical installation | Q9: =LEFT(P9,5) -> 02.02 | R9: =SUBSTITUTE(Q9," "&"-","") -> 02.02
A10: =P10 -> 02.03 - Data installation | B10: =LEFT(A10,5)&C10 -> 02.03.02 | C10: =IF(COUNTIFS(Budget_items[Subheaders],'Data entry'!A10)<10,".0"&COUNTIFS(Budget_items[Subheaders],'Data entry'!A10),"."&COUNTIFS(Budget_items[Subheaders],'Data entry'!A10)) -> .02 | P10: 02.03 - Data installation | Q10: =LEFT(P10,5) -> 02.03 | R10: =SUBSTITUTE(Q10," "&"-","") -> 02.03
A11: =P11 -> 02.04 - Security installation & access control | B11: =LEFT(A11,5)&C11 -> 02.04.02 | C11: =IF(COUNTIFS(Budget_items[Subheaders],'Data entry'!A11)<10,".0"&COUNTIFS(Budget_items[Subheaders],'Data entry'!A11),"."&COUNTIFS(Budget_items[Subheaders],'Data entry'!A11)) -> .02 | P11: 02.04 - Security installation & access control | Q11: =LEFT(P11,5) -> 02.04 | R11: =SUBSTITUTE(Q11," "&"-","") -> 02.04
A12: =P12 -> 02.05 - Fire safety installation | B12: =LEFT(A12,5)&C12 -> 02.05.01 | C12: =IF(COUNTIFS(Budget_items[Subheaders],'Data entry'!A12)<10,".0"&COUNTIFS(Budget_items[Subheaders],'Data entry'!A12),"."&COUNTIFS(Budget_items[Subheaders],'Data entry'!A12)) -> .01 | P12: 02.05 - Fire safety installation | Q12: =LEFT(P12,5) -> 02.05 | R12: =SUBSTITUTE(Q12," "&"-","") -> 02.05
A13: =P13 -> 02.06 - Audiovisual installation | B13: =LEFT(A13,5)&C13 -> 02.06.04 | C13: =IF(COUNTIFS(Budget_items[Subheaders],'Data entry'!A13)<10,".0"&COUNTIFS(Budget_items[Subheaders],'Data entry'!A13),"."&COUNTIFS(Budget_items[Subheaders],'Data entry'!A13)) -> .04 | P13: 02.06 - Audiovisual installation | Q13: =LEFT(P13,5) -> 02.06 | R13: =SUBSTITUTE(Q13," "&"-","") -> 02.06
A14: =P14 -> 03.01 - Joinery | B14: =LEFT(A14,5)&C14 -> 03.01.08 | C14: =IF(COUNTIFS(Budget_items[Subheaders],'Data entry'!A14)<10,".0"&COUNTIFS(Budget_items[Subheaders],'Data entry'!A14),"."&COUNTIFS(Budget_items[Subheaders],'Data entry'!A14)) -> .08 | P14: 03.01 - Joinery | Q14: =LEFT(P14,5) -> 03.01 | R14: =SUBSTITUTE(Q14," "&"-","") -> 03.01
A15: =P15 -> 04.01 - Workplace furniture | B15: =LEFT(A15,5)&C15 -> 04.01.04 | C15: =IF(COUNTIFS(Budget_items[Subheaders],'Data entry'!A15)<10,".0"&COUNTIFS(Budget_items[Subheaders],'Data entry'!A15),"."&COUNTIFS(Budget_items[Subheaders],'Data entry'!A15)) -> .04 | P15: 04.01 - Workplace furniture | Q15: =LEFT(P15,5) -> 04.01 | R15: =SUBSTITUTE(Q15," "&"-","") -> 04.01
A16: =#REF! -> #REF! | B16: =LEFT(A16,5)&C16 -> #REF! | C16: =IF(COUNTIFS(Budget_items[Subheaders],'Data entry'!A16)<10,".0"&COUNTIFS(Budget_items[Subheaders],'Data entry'!A16),"."&COUNTIFS(Budget_items[Subheaders],'Data entry'!A16)) -> .00 | P16: 04.02 - Meeting furniture | Q16: =LEFT(P16,5) -> 04.02 | R16: =SUBSTITUTE(Q16," "&"-","") -> 04.02
A17: =P16 -> 04.02 - Meeting furniture | B17: =LEFT(A17,5)&C17 -> 04.02.04 | C17: =IF(COUNTIFS(Budget_items[Subheaders],'Data entry'!A17)<10,".0"&COUNTIFS(Budget_items[Subheaders],'Data entry'!A17),"."&COUNTIFS(Budget_items[Subheaders],'Data entry'!A17)) -> .04 | P17: 04.03 - Loose furniture | Q17: =LEFT(P17,5) -> 04.03 | R17: =SUBSTITUTE(Q17," "&"-","") -> 04.03
A18: =P17 -> 04.03 - Loose furniture | B18: =LEFT(A18,5)&C18 -> 04.03.07 | C18: =IF(COUNTIFS(Budget_items[Subheaders],'Data entry'!A18)<10,".0"&COUNTIFS(Budget_items[Subheaders],'Data entry'!A18),"."&COUNTIFS(Budget_items[Subheaders],'Data entry'!A18)) -> .07 | P18: 05.01 - Inventory & decorations | Q18: =LEFT(P18,5) -> 05.01 | R18: =SUBSTITUTE(Q18," "&"-","") -> 05.01
A19: =P18 -> 05.01 - Inventory & decorations | B19: =LEFT(A19,5)&C19 -> 05.01.06 | C19: =IF(COUNTIFS(Budget_items[Subheaders],'Data entry'!A19)<10,".0"&COUNTIFS(Budget_items[Subheaders],'Data entry'!A19),"."&COUNTIFS(Budget_items[Subheaders],'Data entry'!A19)) -> .06 | P19: 06.01 - Move | Q19: =LEFT(P19,5) -> 06.01 | R19: =SUBSTITUTE(Q19," "&"-","") -> 06.01
A20: =P19 -> 06.01 - Move | B20: =LEFT(A20,5)&C20 -> 06.01.02 | C20: =IF(COUNTIFS(Budget_items[Subheaders],'Data entry'!A20)<10,".0"&COUNTIFS(Budget_items[Subheaders],'Data entry'!A20),"."&COUNTIFS(Budget_items[Subheaders],'Data entry'!A20)) -> .02 | P20: 07.01 - Consultancy costs | Q20: =LEFT(P20,5) -> 07.01 | R20: =SUBSTITUTE(Q20," "&"-","") -> 07.01
A21: =#REF! -> #REF! | B21: =LEFT(A21,5)&C21 -> #REF! | C21: =IF(COUNTIFS(Budget_items[Subheaders],'Data entry'!A21)<10,".0"&COUNTIFS(Budget_items[Subheaders],'Data entry'!A21),"."&COUNTIFS(Budget_items[Subheaders],'Data entry'!A21)) -> .00 | P21: 08.01 - Contingency | Q21: =LEFT(P21,5) -> 08.01 | R21: =SUBSTITUTE(Q21," "&"-","") -> 08.01
A22: =P21 -> 08.01 - Contingency | B22: =LEFT(A22,5)&C22 -> 08.01.01 | C22: =IF(COUNTIFS(Budget_items[Subheaders],'Data entry'!A22)<10,".0"&COUNTIFS(Budget_items[Subheaders],'Data entry'!A22),"."&COUNTIFS(Budget_items[Subheaders],'Data entry'!A22)) -> .01 | Q22: =LEFT(P22,5) | R22: =SUBSTITUTE(Q22," "&"-","")
A23: =#REF! -> #REF! | B23: =LEFT(A23,5)&C23 -> #REF! | C23: =IF(COUNTIFS(Budget_items[Subheaders],'Data entry'!A23)<10,".0"&COUNTIFS(Budget_items[Subheaders],'Data entry'!A23),"."&COUNTIFS(Budget_items[Subheaders],'Data entry'!A23)) -> .00
A24: =P24 -> 0 | B24: =LEFT(A24,4)&C24 -> 0.00 | C24: =IF(COUNTIFS(Budget_items[Subheaders],'Data entry'!A24)<10,".0"&COUNTIFS(Budget_items[Subheaders],'Data entry'!A24),"."&COUNTIFS(Budget_items[Subheaders],'Data entry'!A24)) -> .00
A25: =P25 -> 0 | B25: =LEFT(A25,4)&C25 -> 0.00 | C25: =IF(COUNTIFS(Budget_items[Subheaders],'Data entry'!A25)<10,".0"&COUNTIFS(Budget_items[Subheaders],'Data entry'!A25),"."&COUNTIFS(Budget_items[Subheaders],'Data entry'!A25)) -> .00
A26: =P28 -> 0 | B26: =LEFT(A26,4)&C26 -> 0.00 | C26: =IF(COUNTIFS(Budget_items[Subheaders],'Data entry'!A26)<10,".0"&COUNTIFS(Budget_items[Subheaders],'Data entry'!A26),"."&COUNTIFS(Budget_items[Subheaders],'Data entry'!A26)) -> .00
A27: =P29 -> 0 | B27: =LEFT(A27,4)&C27 -> 0.00 | C27: =IF(COUNTIFS(Budget_items[Subheaders],'Data entry'!A27)<10,".0"&COUNTIFS(Budget_items[Subheaders],'Data entry'!A27),"."&COUNTIFS(Budget_items[Subheaders],'Data entry'!A27)) -> .00
A28: =P30 -> 0 | B28: =LEFT(A28,4)&C28 -> 0.00 | C28: =IF(COUNTIFS(Budget_items[Subheaders],'Data entry'!A28)<10,".0"&COUNTIFS(Budget_items[Subheaders],'Data entry'!A28),"."&COUNTIFS(Budget_items[Subheaders],'Data entry'!A28)) -> .00
A29: =P31 -> 0 | B29: =LEFT(A29,4)&C29 -> 0.00 | C29: =IF(COUNTIFS(Budget_items[Subheaders],'Data entry'!A29)<10,".0"&COUNTIFS(Budget_items[Subheaders],'Data entry'!A29),"."&COUNTIFS(Budget_items[Subheaders],'Data entry'!A29)) -> .00
A30: =P32 -> 0 | B30: =LEFT(A30,4)&C30 -> 0.00 | C30: =IF(COUNTIFS(Budget_items[Subheaders],'Data entry'!A30)<10,".0"&COUNTIFS(Budget_items[Subheaders],'Data entry'!A30),"."&COUNTIFS(Budget_items[Subheaders],'Data entry'!A30)) -> .00
A31: =P33 -> 0 | B31: =LEFT(A31,4)&C31 -> 0.00 | C31: =IF(COUNTIFS(Budget_items[Subheaders],'Data entry'!A31)<10,".0"&COUNTIFS(Budget_items[Subheaders],'Data entry'!A31),"."&COUNTIFS(Budget_items[Subheaders],'Data entry'!A31)) -> .00
A32: =P34 -> 0 | B32: =LEFT(A32,4)&C32 -> 0.00 | C32: =IF(COUNTIFS(Budget_items[Subheaders],'Data entry'!A32)<10,".0"&COUNTIFS(Budget_items[Subheaders],'Data entry'!A32),"."&COUNTIFS(Budget_items[Subheaders],'Data entry'!A32)) -> .00
A33: =P35 -> 0 | B33: =LEFT(A33,4)&C33 -> 0.00 | C33: =IF(COUNTIFS(Budget_items[Subheaders],'Data entry'!A33)<10,".0"&COUNTIFS(Budget_items[Subheaders],'Data entry'!A33),"."&COUNTIFS(Budget_items[Subheaders],'Data entry'!A33)) -> .00
A34: =P36 -> 0 | B34: =LEFT(A34,4)&C34 -> 0.00 | C34: =IF(COUNTIFS(Budget_items[Subheaders],'Data entry'!A34)<10,".0"&COUNTIFS(Budget_items[Subheaders],'Data entry'!A34),"."&COUNTIFS(Budget_items[Subheaders],'Data entry'!A34)) -> .00
A35: =P37 -> 0 | B35: =LEFT(A35,4)&C35 -> 0.00 | C35: =IF(COUNTIFS(Budget_items[Subheaders],'Data entry'!A35)<10,".0"&COUNTIFS(Budget_items[Subheaders],'Data entry'!A35),"."&COUNTIFS(Budget_items[Subheaders],'Data entry'!A35)) -> .00
A36: =P38 -> 0 | B36: =LEFT(A36,4)&C36 -> 0.00 | C36: =IF(COUNTIFS(Budget_items[Subheaders],'Data entry'!A36)<10,".0"&COUNTIFS(Budget_items[Subheaders],'Data entry'!A36),"."&COUNTIFS(Budget_items[Subheaders],'Data entry'!A36)) -> .00
A37: =P39 -> 0 | B37: =LEFT(A37,4)&C37 -> 0.00 | C37: =IF(COUNTIFS(Budget_items[Subheaders],'Data entry'!A37)<10,".0"&COUNTIFS(Budget_items[Subheaders],'Data entry'!A37),"."&COUNTIFS(Budget_items[Subheaders],'Data entry'!A37)) -> .00
... A574: =P576 -> 0 | B574: =LEFT(A574,4)&C574 -> 0.00 | C574: =IF(COUNTIFS(Budget_items[Subheaders],'Data entry'!A574)<10,".0"&COUNTIFS(Budget_items[Subheaders],'Data entry'!A574),"."&COUNTIFS(Budget_items[Subheaders],'Data entry'!A574)) -> .00
A575: =P577 -> 0 | B575: =LEFT(A575,4)&C575 -> 0
A576: =P578 -> 0 | B576: =LEFT(A576,4)&C576 -> 0
...

Sheet Eenheidsprijzenoverzicht
A1: Code | B1: Description | C1: € / Unit | D1: € / Unit + Finishing
A2: =Budget_items[[#This Row],[Code]] -> 1.01.01 | B2: =Budget_items[[#This Row],[Description]] -> General construction site costs (cleaning, waste, coffee, temporary cylinders etc.) | C2: =Budget_items[[#This Row],[€ / Unit]] -> 5 | D2: =Budget_items[[#This Row],[€ / Unit + Finishing]] -> 5
A3: =Budget_items[[#This Row],[Code]] -> 1.01.02 | B3: =Budget_items[[#This Row],[Description]] -> Vertical transportation | C3: =Budget_items[[#This Row],[€ / Unit]] -> 1500 | D3: =Budget_items[[#This Row],[€ / Unit + Finishing]] -> 1500
A4: =Budget_items[[#This Row],[Code]] -> 1.01.03 | B4: =Budget_items[[#This Row],[Description]] -> Delivery cleaning / final cleaning | C4: =Budget_items[[#This Row],[€ / Unit]] -> 4 | D4: =Budget_items[[#This Row],[€ / Unit + Finishing]] -> 4
A5: =Budget_items[[#This Row],[Code]] -> 1.01.04 | B5: =Budget_items[[#This Row],[Description]] -> Project coordination (contractor) + parking costs | C5: =Budget_items[[#This Row],[€ / Unit]] -> 1500 | D5: =Budget_items[[#This Row],[€ / Unit + Finishing]] -> 1500
A6: =Budget_items[[#This Row],[Code]] -> 1.01.05 | B6: =Budget_items[[#This Row],[Description]] -> Werktekeningen en revisie | C6: =Budget_items[[#This Row],[€ / Unit]] -> 2000 | D6: =Budget_items[[#This Row],[€ / Unit + Finishing]] -> 2000
A7: =Budget_items[[#This Row],[Code]] -> 1.01.06 | B7: =Budget_items[[#This Row],[Description]] -> Overhead + profit and risk + CAR insurance (Ak + wr + carverzekering) | C7: =Budget_items[[#This Row],[€ / Unit]] -> 0 | D7: =Budget_items[[#This Row],[€ / Unit + Finishing]] -> 0
A8: =Budget_items[[#This Row],[Code]] -> 1.01.07 | B8: =Budget_items[[#This Row],[Description]] -> * Waste fee (stortleges) (65 euro per m3) | C8: =Budget_items[[#This Row],[€ / Unit]] -> 2500 | D8: =Budget_items[[#This Row],[€ / Unit + Finishing]] -> 2500
A9: =Budget_items[[#This Row],[Code]] -> 1.02.01 | B9: =Budget_items[[#This Row],[Description]] -> Demolition and disposal carpeting | C9: =Budget_items[[#This Row],[€ / Unit]] -> 5 | D9: =Budget_items[[#This Row],[€ / Unit + Finishing]] -> 5
A10: =Budget_items[[#This Row],[Code]] -> 1.02.02 | B10: =Budget_items[[#This Row],[Description]] -> Demolition and disposal partitioning | C10: =Budget_items[[#This Row],[€ / Unit]] -> 25 | D10: =Budget_items[[#This Row],[€ / Unit + Finishing]] -> 25
A11: =Budget_items[[#This Row],[Code]] -> 1.02.03 | B11: =Budget_items[[#This Row],[Description]] -> Demolition and disposal ceiling | C11: =Budget_items[[#This Row],[€ / Unit]] -> 10 | D11: =Budget_items[[#This Row],[€ / Unit + Finishing]] -> 10
A12: =Budget_items[[#This Row],[Code]] -> 1.02.04 | B12: =Budget_items[[#This Row],[Description]] -> Demolition and disposal loose furniture / inventory | C12: =Budget_items[[#This Row],[€ / Unit]] -> 3500 | D12: =Budget_items[[#This Row],[€ / Unit + Finishing]] -> 3500
A13: =Budget_items[[#This Row],[Code]] -> 1.03.01 | B13: =Budget_items[[#This Row],[Description]] -> * Solid walls including finishes | C13: =Budget_items[[#This Row],[€ / Unit]] -> 122 | D13: =Budget_items[[#This Row],[€ / Unit + Finishing]] -> 122
... A92: =Budget_items[[#This Row],[Code]] -> #VALUE! | B92: =Budget_items[[#This Row],[Description]] -> #VALUE! | C92: =Budget_items[[#This Row],[€ / Unit]] -> #VALUE! | D92: =Budget_items[[#This Row],[€ / Unit + Finishing]] -> #VALUE!

Sheet Report

Sheet Row
C1: Units | E1: High +10% | F1: {=_xlfn.IFS(Dashboard!B4=Row!E1,1.1,Dashboard!B4=Row!E2,1,Dashboard!B4=Row!E3,0.95)} -> 1
A2: {=_xlfn.UNIQUE(Budget_items[Headers])} -> 01 - CONSTRUCTION COSTS | B2: {=_xlfn.UNIQUE(Budget_items[Subheaders])} -> 01.01 - General construction | C2: lot | E2: Medium +0%
A3: 02 - INSTALLATIONS | B3: 01.02 - Demolition | C3: m | E3: Low -5%
A4: 03 - JOINERY | B4: 01.03 - Partitioning | C4: m²
A5: 04 - FURNITURE | B5: 01.04 - Ceiling | C5: m³
A6: 05 - INVENTORY AND DECORATIONS | B6: 01.05 - Flooring | C6: pieces
A7: 06 - OTHERS | B7: 01.06 - Painting | C7: hours
A8: 07 - CONSULTANCY COSTS | B8: 02.01 - Mechanical installation & plumbing | C8: weeks
A9: 08 - CONTINGENCY | B9: 02.02 - Electrical installation | C9: day
B10: 02.03 - Data installation | C10: connection
B11: 02.04 - Security installation & access control | C11: room
B12: 02.05 - Fire safety installation | C12: seat
B13: 02.06 - Audiovisual installation | C13: person
B14: 03.01 - Joinery
B15: 04.01 - Workplace furniture
B16: 04.02 - Meeting furniture
B17: 04.03 - Loose furniture
B18: 05.01 - Inventory & decorations
B19: 06.01 - Move
B20: 07.01 - Consultancy costs
B21: 08.01 - Contingency
